<sdf version='1.6'>
  <world name='default'>
    <light name='sun' type='directional'>
      <cast_shadows>1</cast_shadows>
      <pose frame=''>0 0 10 0 -0 0</pose>
      <diffuse>0.8 0.8 0.8 1</diffuse>
      <specular>0.1 0.1 0.1 1</specular>
      <attenuation>
        <range>1000</range>
        <constant>0.9</constant>
        <linear>0.01</linear>
        <quadratic>0.001</quadratic>
      </attenuation>
      <direction>-0.5 0.5 -1</direction>
    </light>
    <model name='ground_plane'>
      <static>1</static>
      <link name='link'>
        <collision name='collision'>
          <geometry>
            <plane>
              <normal>0 0 1</normal>
              <size>100 100</size>
            </plane>
          </geometry>
          <surface>
            <friction>
              <ode>
                <mu>100</mu>
                <mu2>50</mu2>
              </ode>
              <torsional>
                <ode/>
              </torsional>
            </friction>
            <contact>
              <ode/>
            </contact>
            <bounce/>
          </surface>
          <max_contacts>10</max_contacts>
        </collision>
        <visual name='visual'>
          <cast_shadows>0</cast_shadows>
          <geometry>
            <plane>
              <normal>0 0 1</normal>
              <size>100 100</size>
            </plane>
          </geometry>
          <material>
            <script>
              <uri>file://media/materials/scripts/gazebo.material</uri>
              <name>Gazebo/Grey</name>
            </script>
          </material>
        </visual>
        <self_collide>0</self_collide>
        <kinematic>0</kinematic>
        <gravity>1</gravity>
      </link>
    </model>
    <gravity>0 0 -9.8</gravity>
    <magnetic_field>6e-06 2.3e-05 -4.2e-05</magnetic_field>
    <atmosphere type='adiabatic'/>
    <physics name='default_physics' default='0' type='ode'>
      <max_step_size>0.001</max_step_size>
      <real_time_factor>1</real_time_factor>
      <real_time_update_rate>1000</real_time_update_rate>
    </physics>
    <scene>
      <ambient>0.4 0.4 0.4 1</ambient>
      <background>0.7 0.7 0.7 1</background>
      <shadows>1</shadows>
    </scene>
    <spherical_coordinates>
      <surface_model>EARTH_WGS84</surface_model>
      <latitude_deg>0</latitude_deg>
      <longitude_deg>0</longitude_deg>
      <elevation>0</elevation>
      <heading_deg>0</heading_deg>
    </spherical_coordinates>
    <model name='panda'>
      <link name='panda_link0'>
        <pose frame=''>0 0 0 0 -0 0</pose>
        <inertial>
          <pose frame=''>-0.025566 -2.9e-05 0.057332 0 -0 0</pose>
          <mass>2.92</mass>
          <inertia>
            <ixx>0.00782229</ixx>
            <ixy>-1.56192e-05</ixy>
            <ixz>-0.00126006</ixz>
            <iyy>0.0109028</iyy>
            <iyz>1.08234e-05</iyz>
            <izz>0.0102356</izz>
          </inertia>
        </inertial>
        <collision name='panda_link0_collision'>
          <pose frame=''>0 0 0 0 -0 0</pose>
          <geometry>
            <mesh>
              <scale>1 1 1</scale>
              <uri>/home/zy2016/ws_moveit/src/franka_gazebo/meshes/collision/link0.stl</uri>
            </mesh>
          </geometry>
          <max_contacts>10</max_contacts>
          <surface>
            <contact>
              <ode/>
            </contact>
            <bounce/>
            <friction>
              <torsional>
                <ode/>
              </torsional>
              <ode/>
            </friction>
          </surface>
        </collision>
        <visual name='panda_link0_visual'>
          <pose frame=''>0 0 0 0 -0 0</pose>
          <geometry>
            <mesh>
              <scale>1 1 1</scale>
              <uri>/home/zy2016/ws_moveit/src/franka_gazebo/meshes/visual/link0.dae</uri>
            </mesh>
          </geometry>
        </visual>
        <gravity>1</gravity>
        <velocity_decay/>
        <self_collide>0</self_collide>
        <kinematic>0</kinematic>
      </link>
      <joint name='panda_joint_world' type='revolute'>
        <child>panda_link0</child>
        <parent>world</parent>
        <axis>
          <limit>
            <lower>0</lower>
            <upper>0</upper>
          </limit>
          <dynamics>
            <damping>0</damping>
            <friction>0</friction>
            <spring_reference>0</spring_reference>
            <spring_stiffness>0</spring_stiffness>
          </dynamics>
          <use_parent_model_frame>1</use_parent_model_frame>
          <xyz>0 0 1</xyz>
        </axis>
      </joint>
      <link name='panda_link1'>
        <pose frame=''>0 0 0.333 0 -0 0</pose>
        <inertial>
          <pose frame=''>0 -0.032496 -0.067582 0 -0 0</pose>
          <mass>2.74</mass>
          <inertia>
            <ixx>0.0180417</ixx>
            <ixy>0</ixy>
            <ixz>0</ixz>
            <iyy>0.0159136</iyy>
            <iyz>0.00467584</iyz>
            <izz>0.00620691</izz>
          </inertia>
        </inertial>
        <collision name='panda_link1_collision'>
          <pose frame=''>0 0 0 0 -0 0</pose>
          <geometry>
            <mesh>
              <scale>1 1 1</scale>
              <uri>/home/zy2016/ws_moveit/src/franka_gazebo/meshes/collision/link1.stl</uri>
            </mesh>
          </geometry>
          <max_contacts>10</max_contacts>
          <surface>
            <contact>
              <ode/>
            </contact>
            <bounce/>
            <friction>
              <torsional>
                <ode/>
              </torsional>
              <ode/>
            </friction>
          </surface>
        </collision>
        <visual name='panda_link1_visual'>
          <pose frame=''>0 0 0 0 -0 0</pose>
          <geometry>
            <mesh>
              <scale>1 1 1</scale>
              <uri>/home/zy2016/ws_moveit/src/franka_gazebo/meshes/visual/link1.dae</uri>
            </mesh>
          </geometry>
        </visual>
        <gravity>1</gravity>
        <velocity_decay/>
        <self_collide>0</self_collide>
        <kinematic>0</kinematic>
      </link>
      <joint name='panda_joint1' type='revolute'>
        <child>panda_link1</child>
        <parent>panda_link0</parent>
        <axis>
          <xyz>0 0 1</xyz>
          <limit>
            <lower>-2.8973</lower>
            <upper>2.8973</upper>
            <effort>87</effort>
            <velocity>2.175</velocity>
          </limit>
          <dynamics>
            <spring_reference>0</spring_reference>
            <spring_stiffness>0</spring_stiffness>
          </dynamics>
          <use_parent_model_frame>1</use_parent_model_frame>
        </axis>
      </joint>
      <link name='panda_link2'>
        <pose frame=''>0 0 0.333 -1.5708 0 0</pose>
        <inertial>
          <pose frame=''>0 -0.06861 0.032229 0 -0 0</pose>
          <mass>2.74</mass>
          <inertia>
            <ixx>0.0182856</ixx>
            <ixy>0</ixy>
            <ixz>0</ixz>
            <iyy>0.00621358</iyy>
            <iyz>-0.00472844</iyz>
            <izz>0.0161514</izz>
          </inertia>
        </inertial>
        <collision name='panda_link2_collision'>
          <pose frame=''>0 0 0 0 -0 0</pose>
          <geometry>
            <mesh>
              <scale>1 1 1</scale>
              <uri>/home/zy2016/ws_moveit/src/franka_gazebo/meshes/collision/link2.stl</uri>
            </mesh>
          </geometry>
          <max_contacts>10</max_contacts>
          <surface>
            <contact>
              <ode/>
            </contact>
            <bounce/>
            <friction>
              <torsional>
                <ode/>
              </torsional>
              <ode/>
            </friction>
          </surface>
        </collision>
        <visual name='panda_link2_visual'>
          <pose frame=''>0 0 0 0 -0 0</pose>
          <geometry>
            <mesh>
              <scale>1 1 1</scale>
              <uri>/home/zy2016/ws_moveit/src/franka_gazebo/meshes/visual/link2.dae</uri>
            </mesh>
          </geometry>
        </visual>
        <gravity>1</gravity>
        <velocity_decay/>
        <self_collide>0</self_collide>
        <kinematic>0</kinematic>
      </link>
      <joint name='panda_joint2' type='revolute'>
        <child>panda_link2</child>
        <parent>panda_link1</parent>
        <axis>
          <xyz>0 1 0</xyz>
          <limit>
            <lower>-1.7628</lower>
            <upper>1.7628</upper>
            <effort>87</effort>
            <velocity>2.175</velocity>
          </limit>
          <dynamics>
            <spring_reference>0</spring_reference>
            <spring_stiffness>0</spring_stiffness>
          </dynamics>
          <use_parent_model_frame>1</use_parent_model_frame>
        </axis>
      </joint>
      <link name='panda_link3'>
        <pose frame=''>0 -0 0.649 0 -0 0</pose>
        <inertial>
          <pose frame=''>0.046989 0.031637 -0.031704 0 -0 0</pose>
          <mass>2.38</mass>
          <inertia>
            <ixx>0.00771377</ixx>
            <ixy>-0.00248491</ixy>
            <ixz>-0.00332148</ixz>
            <iyy>0.00989108</iyy>
            <iyz>-0.00217796</iyz>
            <izz>0.00811724</izz>
          </inertia>
        </inertial>
        <collision name='panda_link3_collision'>
          <pose frame=''>0 0 0 0 -0 0</pose>
          <geometry>
            <mesh>
              <scale>1 1 1</scale>
              <uri>/home/zy2016/ws_moveit/src/franka_gazebo/meshes/collision/link3.stl</uri>
            </mesh>
          </geometry>
          <max_contacts>10</max_contacts>
          <surface>
            <contact>
              <ode/>
            </contact>
            <bounce/>
            <friction>
              <torsional>
                <ode/>
              </torsional>
              <ode/>
            </friction>
          </surface>
        </collision>
        <visual name='panda_link3_visual'>
          <pose frame=''>0 0 0 0 -0 0</pose>
          <geometry>
            <mesh>
              <scale>1 1 1</scale>
              <uri>/home/zy2016/ws_moveit/src/franka_gazebo/meshes/visual/link3.dae</uri>
            </mesh>
          </geometry>
        </visual>
        <gravity>1</gravity>
        <velocity_decay/>
        <self_collide>0</self_collide>
        <kinematic>0</kinematic>
      </link>
      <joint name='panda_joint3' type='revolute'>
        <child>panda_link3</child>
        <parent>panda_link2</parent>
        <axis>
          <xyz>0 0 1</xyz>
          <limit>
            <lower>-2.8973</lower>
            <upper>2.8973</upper>
            <effort>87</effort>
            <velocity>2.175</velocity>
          </limit>
          <dynamics>
            <spring_reference>0</spring_reference>
            <spring_stiffness>0</spring_stiffness>
          </dynamics>
          <use_parent_model_frame>1</use_parent_model_frame>
        </axis>
      </joint>
      <link name='panda_link4'>
        <pose frame=''>0.0825 -0 0.649 1.5708 -0 0</pose>
        <inertial>
          <pose frame=''>-0.036045 0.033685 0.031882 0 -0 0</pose>
          <mass>2.38</mass>
          <inertia>
            <ixx>0.00799664</ixx>
            <ixy>0.00347096</ixy>
            <ixz>-0.00241223</ixz>
            <iyy>0.00825391</iyy>
            <iyz>0.00235774</iyz>
            <izz>0.0102515</izz>
          </inertia>
        </inertial>
        <collision name='panda_link4_collision'>
          <pose frame=''>0 0 0 0 -0 0</pose>
          <geometry>
            <mesh>
              <scale>1 1 1</scale>
              <uri>/home/zy2016/ws_moveit/src/franka_gazebo/meshes/collision/link4.stl</uri>
            </mesh>
          </geometry>
          <max_contacts>10</max_contacts>
          <surface>
            <contact>
              <ode/>
            </contact>
            <bounce/>
            <friction>
              <torsional>
                <ode/>
              </torsional>
              <ode/>
            </friction>
          </surface>
        </collision>
        <visual name='panda_link4_visual'>
          <pose frame=''>0 0 0 0 -0 0</pose>
          <geometry>
            <mesh>
              <scale>1 1 1</scale>
              <uri>/home/zy2016/ws_moveit/src/franka_gazebo/meshes/visual/link4.dae</uri>
            </mesh>
          </geometry>
        </visual>
        <gravity>1</gravity>
        <velocity_decay/>
        <self_collide>0</self_collide>
        <kinematic>0</kinematic>
      </link>
      <joint name='panda_joint4' type='revolute'>
        <child>panda_link4</child>
        <parent>panda_link3</parent>
        <axis>
          <xyz>0 -1 0</xyz>
          <limit>
            <lower>-3.0718</lower>
            <upper>0.0698</upper>
            <effort>87</effort>
            <velocity>2.175</velocity>
          </limit>
          <dynamics>
            <spring_reference>0</spring_reference>
            <spring_stiffness>0</spring_stiffness>
          </dynamics>
          <use_parent_model_frame>1</use_parent_model_frame>
        </axis>
      </joint>
      <link name='panda_link5'>
        <pose frame=''>-0 0 1.033 0 -0 0</pose>
        <inertial>
          <pose frame=''>0 0.061043 -0.104176 0 -0 0</pose>
          <mass>2.74</mass>
          <inertia>
            <ixx>0.0303714</ixx>
            <ixy>6.50284e-07</ixy>
            <ixz>-1.05129e-05</ixz>
            <iyy>0.0288753</iyy>
            <iyz>-0.00775653</iyz>
            <izz>0.00444134</izz>
          </inertia>
        </inertial>
        <collision name='panda_link5_collision'>
          <pose frame=''>0 0 0 0 -0 0</pose>
          <geometry>
            <mesh>
              <scale>1 1 1</scale>
              <uri>/home/zy2016/ws_moveit/src/franka_gazebo/meshes/collision/link5.stl</uri>
            </mesh>
          </geometry>
          <max_contacts>10</max_contacts>
          <surface>
            <contact>
              <ode/>
            </contact>
            <bounce/>
            <friction>
              <torsional>
                <ode/>
              </torsional>
              <ode/>
            </friction>
          </surface>
        </collision>
        <visual name='panda_link5_visual'>
          <pose frame=''>0 0 0 0 -0 0</pose>
          <geometry>
            <mesh>
              <scale>1 1 1</scale>
              <uri>/home/zy2016/ws_moveit/src/franka_gazebo/meshes/visual/link5.dae</uri>
            </mesh>
          </geometry>
        </visual>
        <gravity>1</gravity>
        <velocity_decay/>
        <self_collide>0</self_collide>
        <kinematic>0</kinematic>
      </link>
      <joint name='panda_joint5' type='revolute'>
        <child>panda_link5</child>
        <parent>panda_link4</parent>
        <axis>
          <xyz>0 0 1</xyz>
          <limit>
            <lower>-2.8973</lower>
            <upper>2.8973</upper>
            <effort>12</effort>
            <velocity>2.61</velocity>
          </limit>
          <dynamics>
            <spring_reference>0</spring_reference>
            <spring_stiffness>0</spring_stiffness>
          </dynamics>
          <use_parent_model_frame>1</use_parent_model_frame>
        </axis>
      </joint>
      <link name='panda_link6'>
        <pose frame=''>-0 0 1.033 1.5708 -0 0</pose>
        <inertial>
          <pose frame=''>0.051051 0.009108 0.010634 0 -0 0</pose>
          <mass>1.55</mass>
          <inertia>
            <ixx>0.00303336</ixx>
            <ixy>-0.000437277</ixy>
            <ixz>0.000629257</ixz>
            <iyy>0.0040448</iyy>
            <iyz>0.000130472</iyz>
            <izz>0.00558234</izz>
          </inertia>
        </inertial>
        <collision name='panda_link6_collision'>
          <pose frame=''>0 0 0 0 -0 0</pose>
          <geometry>
            <mesh>
              <scale>1 1 1</scale>
              <uri>/home/zy2016/ws_moveit/src/franka_gazebo/meshes/collision/link6.stl</uri>
            </mesh>
          </geometry>
          <max_contacts>10</max_contacts>
          <surface>
            <contact>
              <ode/>
            </contact>
            <bounce/>
            <friction>
              <torsional>
                <ode/>
              </torsional>
              <ode/>
            </friction>
          </surface>
        </collision>
        <visual name='panda_link6_visual'>
          <pose frame=''>0 0 0 0 -0 0</pose>
          <geometry>
            <mesh>
              <scale>1 1 1</scale>
              <uri>/home/zy2016/ws_moveit/src/franka_gazebo/meshes/visual/link6.dae</uri>
            </mesh>
          </geometry>
        </visual>
        <gravity>1</gravity>
        <velocity_decay/>
        <self_collide>0</self_collide>
        <kinematic>0</kinematic>
      </link>
      <joint name='panda_joint6' type='revolute'>
        <child>panda_link6</child>
        <parent>panda_link5</parent>
        <axis>
          <xyz>0 -1 0</xyz>
          <limit>
            <lower>-0.0175</lower>
            <upper>3.7525</upper>
            <effort>12</effort>
            <velocity>2.61</velocity>
          </limit>
          <dynamics>
            <spring_reference>0</spring_reference>
            <spring_stiffness>0</spring_stiffness>
          </dynamics>
          <use_parent_model_frame>1</use_parent_model_frame>
        </axis>
      </joint>
      <link name='panda_link7'>
        <pose frame=''>0.088 0 1.033 3.14159 -0 0</pose>
        <inertial>
          <pose frame=''>0.005284 0.00521 0.105019 0 -0 0</pose>
          <mass>1.27</mass>
          <inertia>
            <ixx>0.00401245</ixx>
            <ixy>-0.00134501</ixy>
            <ixz>0.000253409</ixz>
            <iyy>0.00401263</iyy>
            <iyz>0.000116421</iyz>
            <izz>0.00334115</izz>
          </inertia>
        </inertial>
        <collision name='panda_link7_collision'>
          <pose frame=''>0 0 0 0 -0 0</pose>
          <geometry>
            <mesh>
              <scale>1 1 1</scale>
              <uri>/home/zy2016/ws_moveit/src/franka_gazebo/meshes/collision/link7.stl</uri>
            </mesh>
          </geometry>
          <max_contacts>10</max_contacts>
          <surface>
            <contact>
              <ode/>
            </contact>
            <bounce/>
            <friction>
              <torsional>
                <ode/>
              </torsional>
              <ode/>
            </friction>
          </surface>
        </collision>
        <collision name='panda_link7_fixed_joint_lump__panda_hand_collision_1'>
          <pose frame=''>0 0 0.107 0 0 -0.785398</pose>
          <geometry>
            <mesh>
              <scale>1 1 1</scale>
              <uri>/home/zy2016/ws_moveit/src/franka_gazebo/meshes/collision/hand.stl</uri>
            </mesh>
          </geometry>
          <max_contacts>10</max_contacts>
          <surface>
            <contact>
              <ode/>
            </contact>
            <bounce/>
            <friction>
              <torsional>
                <ode/>
              </torsional>
              <ode/>
            </friction>
          </surface>
        </collision>
        <visual name='panda_link7_visual'>
          <pose frame=''>0 0 0 0 -0 0</pose>
          <geometry>
            <mesh>
              <scale>1 1 1</scale>
              <uri>/home/zy2016/ws_moveit/src/franka_gazebo/meshes/visual/link7.dae</uri>
            </mesh>
          </geometry>
        </visual>
        <visual name='panda_link7_fixed_joint_lump__panda_hand_visual_1'>
          <pose frame=''>0 0 0.107 0 0 -0.785398</pose>
          <geometry>
            <mesh>
              <scale>1 1 1</scale>
              <uri>/home/zy2016/ws_moveit/src/franka_gazebo/meshes/visual/hand.dae</uri>
            </mesh>
          </geometry>
        </visual>
        <velocity_decay/>
        <velocity_decay/>
        <gravity>1</gravity>
        <velocity_decay/>
        <self_collide>0</self_collide>
        <kinematic>0</kinematic>
      </link>
      <joint name='panda_joint7' type='revolute'>
        <child>panda_link7</child>
        <parent>panda_link6</parent>
        <axis>
          <xyz>0 0 -1</xyz>
          <limit>
            <lower>-2.8973</lower>
            <upper>2.8973</upper>
            <effort>12</effort>
            <velocity>2.61</velocity>
          </limit>
          <dynamics>
            <spring_reference>0</spring_reference>
            <spring_stiffness>0</spring_stiffness>
          </dynamics>
          <use_parent_model_frame>1</use_parent_model_frame>
        </axis>
      </joint>
      <link name='panda_leftfinger'>
        <pose frame=''>0.088 -0 0.8676 3.14159 -0 0.785398</pose>
        <inertial>
          <pose frame=''>0 0.014564 0.022794 0 -0 0</pose>
          <mass>0.1</mass>
          <inertia>
            <ixx>3.01221e-05</ixx>
            <ixy>0</ixy>
            <ixz>0</ixz>
            <iyy>2.95874e-05</iyy>
            <iyz>0</iyz>
            <izz>6.95125e-06</izz>
          </inertia>
        </inertial>
        <collision name='panda_leftfinger_collision'>
          <pose frame=''>0 0 0 0 -0 0</pose>
          <geometry>
            <mesh>
              <scale>1 1 1</scale>
              <uri>/home/zy2016/ws_moveit/src/franka_gazebo/meshes/collision/finger.stl</uri>
            </mesh>
          </geometry>
          <max_contacts>10</max_contacts>
          <surface>
            <contact>
              <ode/>
            </contact>
            <bounce/>
            <friction>
              <torsional>
                <ode/>
              </torsional>
              <ode/>
            </friction>
          </surface>
        </collision>
        <visual name='panda_leftfinger_visual'>
          <pose frame=''>0 0 0 0 -0 0</pose>
          <geometry>
            <mesh>
              <scale>1 1 1</scale>
              <uri>/home/zy2016/ws_moveit/src/franka_gazebo/meshes/visual/finger.dae</uri>
            </mesh>
          </geometry>
        </visual>
        <gravity>1</gravity>
        <velocity_decay/>
        <self_collide>0</self_collide>
        <kinematic>0</kinematic>
      </link>
      <joint name='panda_finger_joint1' type='prismatic'>
        <child>panda_leftfinger</child>
        <parent>panda_link7</parent>
        <axis>
          <xyz>0.707107 -0.707107 0</xyz>
          <limit>
            <lower>-0.001</lower>
            <upper>0.04</upper>
            <effort>20</effort>
            <velocity>0.3</velocity>
          </limit>
          <dynamics>
            <spring_reference>0</spring_reference>
            <spring_stiffness>0</spring_stiffness>
          </dynamics>
          <use_parent_model_frame>1</use_parent_model_frame>
        </axis>
      </joint>
      <link name='panda_rightfinger'>
        <pose frame=''>0.088 -0 0.8676 3.14159 -0 0.785398</pose>
        <inertial>
          <pose frame=''>0 0.014564 0.022794 0 -0 -3.14159</pose>
          <mass>0.1</mass>
          <inertia>
            <ixx>3.01221e-05</ixx>
            <ixy>0</ixy>
            <ixz>0</ixz>
            <iyy>2.95874e-05</iyy>
            <iyz>0</iyz>
            <izz>6.95125e-06</izz>
          </inertia>
        </inertial>
        <collision name='panda_rightfinger_collision'>
          <pose frame=''>0 0 0 0 -0 -3.14159</pose>
          <geometry>
            <mesh>
              <scale>1 1 1</scale>
              <uri>/home/zy2016/ws_moveit/src/franka_gazebo/meshes/collision/finger.stl</uri>
            </mesh>
          </geometry>
          <max_contacts>10</max_contacts>
          <surface>
            <contact>
              <ode/>
            </contact>
            <bounce/>
            <friction>
              <torsional>
                <ode/>
              </torsional>
              <ode/>
            </friction>
          </surface>
        </collision>
        <visual name='panda_rightfinger_visual'>
          <pose frame=''>0 0 0 0 -0 -3.14159</pose>
          <geometry>
            <mesh>
              <scale>1 1 1</scale>
              <uri>/home/zy2016/ws_moveit/src/franka_gazebo/meshes/visual/finger.dae</uri>
            </mesh>
          </geometry>
        </visual>
        <gravity>1</gravity>
        <velocity_decay/>
        <self_collide>0</self_collide>
        <kinematic>0</kinematic>
      </link>
      <joint name='panda_finger_joint2' type='prismatic'>
        <child>panda_rightfinger</child>
        <parent>panda_link7</parent>
        <axis>
          <xyz>-0.707107 0.707107 -0</xyz>
          <limit>
            <lower>-0.001</lower>
            <upper>0.04</upper>
            <effort>20</effort>
            <velocity>0.3</velocity>
          </limit>
          <dynamics>
            <spring_reference>0</spring_reference>
            <spring_stiffness>0</spring_stiffness>
          </dynamics>
          <use_parent_model_frame>1</use_parent_model_frame>
        </axis>
      </joint>
      <static>0</static>
      <plugin name='gazebo_ros_control' filename='libgazebo_ros_control.so'>
        <robotNamespace>/</robotNamespace>
      </plugin>
      <pose frame=''>0 0 0 0 -0 0</pose>
    </model>
    <model name='Brick'>
      <link name='Brick'>
        <pose frame=''>0 0 0.033 0 -0 0</pose>
        <inertial>
          <pose frame=''>0 -0 0.031 0 -0 0</pose>
          <mass>0.1</mass>
          <inertia>
            <ixx>0.0017</ixx>
            <ixy>0</ixy>
            <ixz>0</ixz>
            <iyy>0.0017</iyy>
            <iyz>0</iyz>
            <izz>0.0017</izz>
          </inertia>
        </inertial>
        <collision name='Brick_collision'>
          <pose frame=''>0 0 0 1.5708 -0 0</pose>
          <geometry>
            <box>
              <size>0.192 0.062 0.086</size>
            </box>
          </geometry>
          <surface>
            <friction>
              <ode>
                <mu>100</mu>
                <mu2>50</mu2>
                <fdir1>0 0 1</fdir1>
                <slip1>0</slip1>
                <slip2>0</slip2>
              </ode>
              <torsional>
                <ode/>
              </torsional>
            </friction>
            <contact>
              <ode>
                <kp>100000</kp>
                <kd>10</kd>
                <max_vel>2</max_vel>
                <min_depth>0.0001</min_depth>
              </ode>
            </contact>
            <bounce/>
          </surface>
          <max_contacts>10</max_contacts>
        </collision>
        <visual name='Brick_visual'>
          <pose frame=''>0 0 0 1.5708 -0 0</pose>
          <geometry>
            <mesh>
              <scale>1 1 1</scale>
              <uri>model://Brick/meshes/Brick_1.STL</uri>
            </mesh>
          </geometry>
          <material>
            <ambient>0.698 0.25 0.25 1</ambient>
            <diffuse>0.698 0.25 0.25 1</diffuse>
            <specular>0.1 0.1 0.1 1</specular>
            <emissive>0 0 0 0</emissive>
          </material>
        </visual>
        <self_collide>0</self_collide>
        <kinematic>0</kinematic>
        <gravity>1</gravity>
      </link>
      <pose frame=''>0.077752 0.295902 0 0 -0 0</pose>
    </model>
    <state world_name='default'>
      <sim_time>1032 584000000</sim_time>
      <real_time>1037 608261091</real_time>
      <wall_time>1550870786 837020452</wall_time>
      <iterations>1032584</iterations>
      <model name='Brick'>
        <pose frame=''>0.5 0.5 0 -4e-06 -0 1.59</pose>
        <scale>1 1 1</scale>
        <link name='Brick'>
          <pose frame=''>0.5 0.5 0.033 -4e-06 -0 1.59</pose>
          <velocity>0 0 0 0 -0 0</velocity>
          <acceleration>0 0 0 0 -0 0</acceleration>
          <wrench>0 0 0 0 -0 0</wrench>
        </link>
      </model>
      <model name='ground_plane'>
        <pose frame=''>0 0 0 0 -0 0</pose>
        <scale>1 1 1</scale>
        <link name='link'>
          <pose frame=''>0 0 0 0 -0 0</pose>
          <velocity>0 0 0 0 -0 0</velocity>
          <acceleration>0 0 0 0 -0 0</acceleration>
          <wrench>0 0 0 0 -0 0</wrench>
        </link>
      </model>
      <model name='panda'>
        <pose frame=''>2e-06 -2.6e-05 1.9e-05 -0.000193 -6.7e-05 -2.1e-05</pose>
        <scale>1 1 1</scale>
        <link name='panda_leftfinger'>
          <pose frame=''>-0.013647 0.482701 0.423381 3.09194 0.032442 0.839028</pose>
          <velocity>0.007231 -0.002616 0.00149 0.112233 0.066373 -0.001595</velocity>
          <acceleration>6.26427 1.04895 -4.73529 -2.81081 -0.301452 1.10111</acceleration>
          <wrench>0.626427 0.104895 -0.473529 0 -0 0</wrench>
        </link>
        <link name='panda_link0'>
          <pose frame=''>2e-06 -2.6e-05 1.9e-05 -0.000193 -6.7e-05 -2.1e-05</pose>
          <velocity>1.2e-05 3.5e-05 0.001139 -0.077817 0.044061 0.0001</velocity>
          <acceleration>2.97935 9.19647 4.40134 -0.310818 0.065616 2.48285</acceleration>
          <wrench>8.69971 26.8537 12.8519 0 -0 0</wrench>
        </link>
        <link name='panda_link1'>
          <pose frame=''>-1.5e-05 -1e-06 0.333018 5.1e-05 2e-05 -2.39654</pose>
          <velocity>0.016102 0.028272 0.000807 -0.094852 0.0467 0.181627</velocity>
          <acceleration>6.53738 35.3401 -0.457655 1.73027 0.537271 2.65352</acceleration>
          <wrench>17.9124 96.8318 -1.25397 0 -0 0</wrench>
        </link>
        <link name='panda_link2'>
          <pose frame=''>-1.5e-05 -2e-06 0.333018 -1.57075 0.255926 -2.39654</pose>
          <velocity>0.01612 0.029228 0.001035 0.105841 -0.175822 0.189573</velocity>
          <acceleration>24.4218 54.4154 -1.03381 -1.0596 0.13987 -0.995396</acceleration>
          <wrench>66.9158 149.098 -2.83264 0 -0 0</wrench>
        </link>
        <link name='panda_link3'>
          <pose frame=''>-0.058824 -0.054225 0.638725 -0.187445 -0.175284 1.57218</pose>
          <velocity>-0.027484 -0.01366 -0.015174 0.146276 -0.139904 -0.027164</velocity>
          <acceleration>-28.7097 -12.4609 -14.9827 -1.57447 1.55499 1.67138</acceleration>
          <wrench>-68.3291 -29.657 -35.6589 0 -0 0</wrench>
        </link>
        <link name='panda_link4'>
          <pose frame=''>-0.058937 0.027011 0.653112 -1.09307 1.16026 -1.15927</pose>
          <velocity>-0.027371 -0.01583 -0.003097 -0.013578 -0.135282 -0.059601</velocity>
          <acceleration>-38.2882 -26.3385 2.11093 0.642979 1.42958 -0.07191</acceleration>
          <wrench>-91.1259 -62.6855 5.02401 0 -0 0</wrench>
        </link>
        <link name='panda_link5'>
          <pose frame=''>-0.035375 0.414377 0.592659 -3.08342 1.20786 -1.61107</pose>
          <velocity>0.003527 -0.017936 -0.005119 0.008226 0.071715 -0.142025</velocity>
          <acceleration>-8.00936 -13.6389 -1.51363 0.149729 -1.20403 -0.627143</acceleration>
          <wrench>-21.9457 -37.3707 -4.14736 0 -0 0</wrench>
        </link>
        <link name='panda_link6'>
          <pose frame=''>-0.035375 0.414377 0.592659 1.55012 0.055586 1.47498</pose>
          <velocity>0.003617 -0.017963 -0.00506 0.11331 0.060703 -0.139722</velocity>
          <acceleration>18.3226 -34.0626 -4.2518 -2.76782 -1.16464 1.65332</acceleration>
          <wrench>28.4 -52.797 -6.59028 0 -0 0</wrench>
        </link>
        <link name='panda_link7'>
          <pose frame=''>-0.026969 0.501838 0.58777 3.08354 -0.012132 0.05478</pose>
          <velocity>0.015711 -0.018527 0.004343 0.111283 0.067323 -0.00302</velocity>
          <acceleration>9.90465 -8.63664 1.2026 -2.19246 -0.234289 1.91509</acceleration>
          <wrench>12.5789 -10.9685 1.5273 0 -0 0</wrench>
        </link>
        <link name='panda_rightfinger'>
          <pose frame=''>-0.035972 0.502686 0.421893 3.09194 0.032441 0.839016</pose>
          <velocity>0.00721 -0.002365 0.005215 0.112649 0.066006 -0.003882</velocity>
          <acceleration>5.97403 1.27388 2.63054 -2.01894 0.11864 -0.276938</acceleration>
          <wrench>0.597403 0.127388 0.263054 0 -0 0</wrench>
        </link>
      </model>
      <light name='sun'>
        <pose frame=''>0 0 10 0 -0 0</pose>
      </light>
    </state>
    <gui fullscreen='0'>
      <camera name='user_camera'>
        <pose frame=''>1.93555 0.999305 0.461063 0 0.079643 -3.07499</pose>
        <view_controller>orbit</view_controller>
        <projection_type>perspective</projection_type>
      </camera>
    </gui>
  </world>
</sdf>
